<?xml version="1.0"?>
<robot  name="aa">
 <link
    name="base_link">
    <inertial>
      <origin
        xyz="0.15 0.15 0.15"
        rpy="0 0 0" />
      <mass
        value="6" />
      <inertia
        ixx="0"
        ixy="0"
        ixz="0"
        iyy="0"
        iyz="0"
        izz="0" />
    </inertial>
    <visual>
      <origin
        xyz="0 0 0"
        rpy="0 0 0" />
      <geometry>
        <mesh
          filename="package://robot_sim/meshes/base_link.STL" />
      </geometry>
      <material
        name="">
        <color
          rgba="0.792156862745098 0.819607843137255 0.933333333333333 1" />
      </material>
    </visual>
    <collision>
      <origin
        xyz="0 0 0"
        rpy="0 0 0" />
      <geometry>
        <mesh
          filename="package://robot_sim/meshes/base_link.STL" />
      </geometry>
    </collision>
  </link>

<link
    name="L1">
    <inertial>
      <origin
        xyz="0.14 0.00999999999999998 0.0647872340425532"
        rpy="0 0 0" />
      <mass
        value="0.188" />
      <inertia
        ixx="0"
        ixy="0"
        ixz="0"
        iyy="0"
        iyz="0"
        izz="0" />
    </inertial>
    <visual>
      <origin
        xyz="0 0 0"
        rpy="0 0 0" />
      <geometry>
        <mesh
          filename="package://robot_sim/meshes/L1.STL" />
      </geometry>
      <material
        name="">
        <color
          rgba="0.792156862745098 0.819607843137255 0.933333333333333 1" />
      </material>
    </visual>
    <collision>
      <origin
        xyz="0 0 0"
        rpy="0 0 0" />
      <geometry>
        <mesh
          filename="package://robot_sim/meshes/L1.STL" />
      </geometry>
    </collision>
  </link>

<joint name="J1" type="prismatic">
   <parent link="base_link"/>
   <child link="L1"/>
   <limit effort="1000.0" lower="-100" upper="100" velocity="0.5"/>
   <origin rpy="0 0 0" xyz="0.01 0.197440112838672 0.2"/>
   <axis
     xyz="0 1 0" />
 </joint>
  <!--joint
    name="J1"
    type="prismatic">
    <origin
      xyz="0.01 0.197440112838672 0.2"
      rpy="0 0 0" />
    <parent
      link="base_link" />
    <child
      link="L1" />
    <axis
      xyz="0 1 0" />
      <limit effort="1000.0" lower="-0.38" upper="0" velocity="0.5"/>

  </joint-->

  <transmission name="j1t">
     <type>transmission_interface/SimpleTransmission</type>
     <actuator name="motor1">
       <mechanicalReduction>1</mechanicalReduction>
     </actuator>
     <joint name="J1">
       <hardwareInterface>hardware_interface/PositionJointInterface</hardwareInterface>
     </joint>
   </transmission>

<link
    name="L2">
    <inertial>
      <origin
        xyz="0.015 0.0014799004971911 0.00165487689757998"
        rpy="0 0 0" />
      <mass
        value="0.00887444678594554" />
      <inertia
        ixx="0"
        ixy="0"
        ixz="0"
        iyy="0"
        iyz="0"
        izz="0" />
    </inertial>
    <visual>
      <origin
        xyz="0 0 0"
        rpy="0 0 0" />
      <geometry>
        <mesh
          filename="package://robot_sim/meshes/L2.STL" />
      </geometry>
      <material
        name="">
        <color
          rgba="0.792156862745098 0.819607843137255 0.933333333333333 1" />
      </material>
    </visual>
    <collision>
      <origin
        xyz="0 0 0"
        rpy="0 0 0" />
      <geometry>
        <mesh
          filename="package://robot_sim/meshes/L2.STL" />
      </geometry>
    </collision>
  </link>

 <joint name="J2" type="prismatic">
    <parent link="L1"/>
    <child link="L2"/>
    <limit effort="1000.0" lower="-100" upper="100" velocity="0.5"/>
    <origin rpy="0 0 0" xyz=".1 0.0 .09"/>

  </joint>

<transmission name="j2t">
     <type>transmission_interface/SimpleTransmission</type>
     <actuator name="motor2">
       <mechanicalReduction>1</mechanicalReduction>
     </actuator>
     <joint name="J2">
       <hardwareInterface>hardware_interface/PositionJointInterface</hardwareInterface>
     </joint>
   </transmission>


<link
    name="L3">
    <inertial>
      <origin
       xyz="0.015 -0.0150 0"
        rpy="0 0 0" />
      <mass
        value="0.0117809724509617" />
      <inertia
        ixx="0"
        ixy="0"
        ixz="0"
        iyy="0"
        iyz="0"
        izz="0" />
    </inertial>
    <visual>
      <origin
        xyz="0.015 -0.0150 0"
        rpy="0 0 0" />
      <geometry>
        <mesh
          filename="package://robot_sim/meshes/L3.STL" />
      </geometry>
      <material
        name="">
        <color
          rgba="0.792156862745098 0.819607843137255 0.933333333333333 1" />
      </material>
    </visual>
    <collision>
      <origin
        xyz="0.015 -0.0150 0"
        rpy="0 0 0" />
      <geometry>
        <mesh
          filename="package://robot_sim/meshes/L3.STL" />
      </geometry>
    </collision>
  </link>


 <joint name="J3" type="prismatic">
    <parent link="L2"/>
    <child link="L3"/>
    <limit effort="1000.0" lower="0" upper="0.09" velocity="0.5"/>
    <origin rpy="0 0 0" xyz="0.0 -0.0 0"/>
    <axis xyz="0 0 -1" />
  </joint>


 <transmission name="j3t">
    <type>transmission_interface/SimpleTransmission</type>
    <actuator name="motor">
      <mechanicalReduction>1</mechanicalReduction>
    </actuator>
    <joint name="J3">
      <hardwareInterface>hardware_interface/PositionJointInterface</hardwareInterface>
    </joint>
  </transmission>



  <!-- Gazebo plugin for ROS Control -->
  <gazebo>
    <plugin name="gazebo_ros_control" filename="libgazebo_ros_control.so">
      <robotNamespace>/</robotNamespace>
    </plugin>
</gazebo>



  </robot>
